<?xml version="1.0" ?>
<!-- =================================================================================== -->
<!-- |    This document was autogenerated by xacro from src/lawn_robot/model/robot.xacro | -->
<!-- |    EDITING THIS FILE BY HAND IS NOT RECOMMENDED                                 | -->
<!-- =================================================================================== -->
<robot name="differential_drive_robot">
  <gazebo reference="body_link">
    <mu1>0.2</mu1>
    <mu2>0.2</mu2>
    <material>
        Gazebo/Grey
    </material>
  </gazebo>
  <gazebo reference="wheel1_link">
    <mu1>0.2</mu1>
    <mu2>0.2</mu2>
    <material>
        Gazebo/DarkGrey
    </material>
  </gazebo>
  <gazebo reference="wheel2_link">
    <mu1>0.2</mu1>
    <mu2>0.2</mu2>
    <material>
        Gazebo/DarkGrey
    </material>
  </gazebo>
  <gazebo reference="wheel3_link">
    <mu1>0.2</mu1>
    <mu2>0.2</mu2>
    <material>
        Gazebo/DarkGrey
    </material>
  </gazebo>
  <gazebo reference="wheel4_link">
    <mu1>0.2</mu1>
    <mu2>0.2</mu2>
    <material>
        Gazebo/DarkGrey
    </material>
  </gazebo>
  <gazebo>
    <plugin filename="libgazebo_ros_diff_drive.so" name="skid_steer_drive">
      <ros>
        <namespace> </namespace>
      </ros>
      <!-- Number of wheel pairs -->
      <num_wheel_pairs>2</num_wheel_pairs>
      <!-- Wheels0 -->
      <left_joint>wheel4_joint</left_joint>
      <right_joint>wheel3_joint</right_joint>
      <!-- Wheels1 -->
      <left_joint>wheel2_joint</left_joint>
      <right_joint>wheel1_joint</right_joint>
      <!-- Kinematics -->
      <wheel_separation>0.36</wheel_separation>
      <wheel_separation>0.36</wheel_separation>
      <wheel_diameter>0.2</wheel_diameter>
      <wheel_diameter>0.2</wheel_diameter>
      <!-- Limits -->
      <max_wheel_torque>1000</max_wheel_torque>
      <max_wheel_acceleration>5.0</max_wheel_acceleration>
      <!-- Output -->
      <publish_odom>true</publish_odom>
      <publish_odom_tf>true</publish_odom_tf>
      <publish_wheel_tf>true</publish_wheel_tf>
      <odometry_frame>odom</odometry_frame>
      <robot_base_frame>dummy</robot_base_frame>
    </plugin>
  </gazebo>
  <!-- ########################################## -->
  <!--         Links and Joints Definition        -->
  <!-- ########################################## -->
  <!-- Dummy link, otherwise Gazebo will complain -->
  <link name="dummy">
</link>
  <joint name="dummy_joint" type="fixed">
    <parent link="dummy"/>
    <child link="body_link"/>
  </joint>
  <!-- ########################################## -->
  <!--           Body Link of the robot           -->
  <!-- ########################################## -->
  <link name="body_link">
    <visual>
      <geometry>
        <mesh filename="package://lawn_robot/meshes/base_link.stl" scale="1 1 1"/>
      </geometry>
      <origin rpy="0.0 0.0 0.0" xyz="0.0 0.0 0.0"/>
    </visual>
    <collision>
      <geometry>
        <box size="0.5 0.33 0.16"/>
      </geometry>
      <origin rpy="0.0 0.0 0.0" xyz="0.0 0.0 0.0"/>
    </collision>
    <inertial>
      <origin rpy="0.0 0.0 0.0" xyz="0.0 0.0 0.0"/>
      <mass value="1.8"/>
      <inertia ixx="0.020175000000000002" ixy="0" ixz="0" iyy="0.04134" iyz="0" izz="0.053835"/>
    </inertial>
  </link>
  <!-- ########################################## -->
  <!--        Back Right Wheel of the robot       -->
  <!-- ########################################## -->
  <joint name="wheel1_joint" type="continuous">
    <parent link="body_link"/>
    <child link="wheel1_link"/>
    <origin rpy="0.0 0.0 0.0" xyz="-0.13 -0.185 0.1"/>
    <axis xyz="0 1 0"/>
    <limit effort="1000" velocity="1000"/>
    <dynamics damping="1.0" friction="1.0"/>
  </joint>
  <link name="wheel1_link">
    <visual>
      <origin rpy="1.570796325 0 0" xyz="0.0 0.0 0.0"/>
      <geometry>
        <cylinder length="0.03" radius="0.1"/>
      </geometry>
    </visual>
    <collision>
      <origin rpy="1.570796325 0 0" xyz="0.0 0.0 0.0"/>
      <geometry>
        <cylinder length="0.03" radius="0.1"/>
      </geometry>
    </collision>
    <inertial>
      <origin rpy="0.0 0.0 0.0" xyz="0.0 0.0 0.0"/>
      <mass value="0.31"/>
      <inertia ixx="0.0007982500000000001" ixy="0.0" ixz="0.0" iyy="0.0007982500000000001" iyz="0.0" izz="0.0015500000000000002"/>
    </inertial>
  </link>
  <!-- ########################################## -->
  <!--        Back Left Wheel of the robot       -->
  <!-- ########################################## -->
  <joint name="wheel2_joint" type="continuous">
    <parent link="body_link"/>
    <child link="wheel2_link"/>
    <origin rpy="0.0 0.0 0.0" xyz="-0.13 0.185 0.1"/>
    <axis xyz="0 1 0"/>
    <limit effort="1000" velocity="1000"/>
    <dynamics damping="1.0" friction="1.0"/>
  </joint>
  <link name="wheel2_link">
    <visual>
      <origin rpy="1.570796325 0 0" xyz="0.0 0.0 0.0"/>
      <geometry>
        <cylinder length="0.03" radius="0.1"/>
      </geometry>
    </visual>
    <collision>
      <origin rpy="1.570796325 0 0" xyz="0.0 0.0 0.0"/>
      <geometry>
        <cylinder length="0.03" radius="0.1"/>
      </geometry>
    </collision>
    <inertial>
      <origin rpy="0.0 0.0 0.0" xyz="0.0 0.0 0.0"/>
      <mass value="0.31"/>
      <inertia ixx="0.0007982500000000001" ixy="0.0" ixz="0.0" iyy="0.0007982500000000001" iyz="0.0" izz="0.0015500000000000002"/>
    </inertial>
  </link>
  <!-- ########################################## -->
  <!--        Front Right Wheel of the robot       -->
  <!-- ########################################## -->
  <joint name="wheel3_joint" type="continuous">
    <parent link="body_link"/>
    <child link="wheel3_link"/>
    <origin rpy="0.0 0.0 0.0" xyz="0.13 -0.185 0.1"/>
    <axis xyz="0 1 0"/>
    <limit effort="1000" velocity="1000"/>
    <dynamics damping="1.0" friction="1.0"/>
  </joint>
  <link name="wheel3_link">
    <visual>
      <origin rpy="1.570796325 0 0" xyz="0.0 0.0 0.0"/>
      <geometry>
        <cylinder length="0.03" radius="0.1"/>
      </geometry>
    </visual>
    <collision>
      <origin rpy="1.570796325 0 0" xyz="0.0 0.0 0.0"/>
      <geometry>
        <cylinder length="0.03" radius="0.1"/>
      </geometry>
    </collision>
    <inertial>
      <origin rpy="0.0 0.0 0.0" xyz="0.0 0.0 0.0"/>
      <mass value="0.31"/>
      <inertia ixx="0.0007982500000000001" ixy="0.0" ixz="0.0" iyy="0.0007982500000000001" iyz="0.0" izz="0.0015500000000000002"/>
    </inertial>
  </link>
  <!-- ########################################## -->
  <!--        Front Right Wheel of the robot       -->
  <!-- ########################################## -->
  <joint name="wheel4_joint" type="continuous">
    <parent link="body_link"/>
    <child link="wheel4_link"/>
    <origin rpy="0.0 0.0 0.0" xyz="0.13 0.185 0.1"/>
    <axis xyz="0 1 0"/>
    <limit effort="1000" velocity="1000"/>
    <dynamics damping="1.0" friction="1.0"/>
  </joint>
  <link name="wheel4_link">
    <visual>
      <origin rpy="1.570796325 0 0" xyz="0.0 0.0 0.0"/>
      <geometry>
        <cylinder length="0.03" radius="0.1"/>
      </geometry>
    </visual>
    <collision>
      <origin rpy="1.570796325 0 0" xyz="0.0 0.0 0.0"/>
      <geometry>
        <cylinder length="0.03" radius="0.1"/>
      </geometry>
    </collision>
    <inertial>
      <origin rpy="0.0 0.0 0.0" xyz="0.0 0.0 0.0"/>
      <mass value="0.31"/>
      <inertia ixx="0.0007982500000000001" ixy="0.0" ixz="0.0" iyy="0.0007982500000000001" iyz="0.0" izz="0.0015500000000000002"/>
    </inertial>
  </link>
</robot>
